/home/hczhai/program/anaconda3/envs/python3.7/bin/python3
Python 3.8.5
2.1.1
/central/groups/changroup/members/hczhai/program/pyscf/pyscf/__init__.py
/central/scratch/hczhai/hife/hs-def2-SVP-uks.7/runs/casci-24
/home/hczhai/program/anaconda3/envs/python3.7/lib/python3.8/site-packages/block2.cpython-38-x86_64-linux-gnu.so
/home/hczhai/program/anaconda3/envs/python3.7/lib/python3.8/site-packages/pyblock2/__init__.py
SLURM_TASKS_PER_NODE=1(x8)
OMP_NUM_THREADS=
SLURM_JOBID=32807843
SLURM_JOB_NAME=hs.24.dmrg
HOST_NAME = hpc-19-13.cm.cluster
PWD = /central/groups/changroup/members/hczhai/work/hife/feh-dimers-new/x2c-dz/hs/runs/casci-24
SLURM_CPUS_PER_TASK=56
/home/hczhai/program/anaconda3/envs/python3.7/bin/orterun
Traceback (most recent call last):
  File "/home/hczhai/program/anaconda3/envs/python3.7/bin/block2main", line 2870, in <module>
    dm = do_npdm(mps, mps, pdm_type=1)
  File "/home/hczhai/program/anaconda3/envs/python3.7/bin/block2main", line 2762, in do_npdm
    pme.init_environments(outputlevel >= 2)
RuntimeError: DataFrame::save_data on '/central/scratch/hczhai/hife/hs-def2-SVP-uks.7/runs/casci-24/F5.PART.NPDM.RIGHT.46' failed.
Traceback (most recent call last):
  File "/home/hczhai/program/anaconda3/envs/python3.7/bin/block2main", line 2870, in <module>
    dm = do_npdm(mps, mps, pdm_type=1)
  File "/home/hczhai/program/anaconda3/envs/python3.7/bin/block2main", line 2762, in do_npdm
    pme.init_environments(outputlevel >= 2)
RuntimeError: DataFrame::save_data on '/central/scratch/hczhai/hife/hs-def2-SVP-uks.7/runs/casci-24/F6.PART.NPDM.RIGHT.52' failed.
Traceback (most recent call last):
  File "/home/hczhai/program/anaconda3/envs/python3.7/bin/block2main", line 2870, in <module>
    dm = do_npdm(mps, mps, pdm_type=1)
  File "/home/hczhai/program/anaconda3/envs/python3.7/bin/block2main", line 2762, in do_npdm
    pme.init_environments(outputlevel >= 2)
RuntimeError: DataFrame::save_data on '/central/scratch/hczhai/hife/hs-def2-SVP-uks.7/runs/casci-24/F0.PART.NPDM.RIGHT.42' failed.
Traceback (most recent call last):
  File "/home/hczhai/program/anaconda3/envs/python3.7/bin/block2main", line 2870, in <module>
    dm = do_npdm(mps, mps, pdm_type=1)
  File "/home/hczhai/program/anaconda3/envs/python3.7/bin/block2main", line 2762, in do_npdm
    pme.init_environments(outputlevel >= 2)
RuntimeError: DataFrame::save_data on '/central/scratch/hczhai/hife/hs-def2-SVP-uks.7/runs/casci-24/F1.PART.NPDM.RIGHT.43' failed.
slurmstepd: error: *** JOB 32807843 ON hpc-19-13 CANCELLED AT 2023-03-25T15:08:12 ***
