/home/hczhai/program/anaconda3/envs/python3.7/bin/python3
Python 3.8.5
2.1.1
/central/groups/changroup/members/hczhai/program/pyscf/pyscf/__init__.py
/central/scratch/hczhai/hife/hfe2-def2-SVP-uks.6/runs/casci-22
/home/hczhai/program/anaconda3/envs/python3.7/lib/python3.8/site-packages/block2.cpython-38-x86_64-linux-gnu.so
/home/hczhai/program/anaconda3/envs/python3.7/lib/python3.8/site-packages/pyblock2/__init__.py
SLURM_TASKS_PER_NODE=1(x6)
OMP_NUM_THREADS=
SLURM_JOBID=32911277
SLURM_JOB_NAME=hfe2.22.drev
HOST_NAME = hpc-21-27.cm.cluster
PWD = /central/groups/changroup/members/hczhai/work/hife/feh-dimers-new/x2c-dz/hfe2/runs/casci-22
SLURM_CPUS_PER_TASK=24
/home/hczhai/program/anaconda3/envs/python3.7/bin/orterun
Traceback (most recent call last):
  File "/home/hczhai/program/anaconda3/envs/python3.7/bin/block2main", line 1379, in <module>
    mps_info.load_data(scratch + "/mps_info.bin")
RuntimeError: MPSInfo:load_data on '/central/scratchio/hczhai/hife/hfe2-def2-SVP-uks.6/runs/casci-22/node0/mps_info.bin' failed.
Traceback (most recent call last):
  File "/home/hczhai/program/anaconda3/envs/python3.7/bin/block2main", line 1379, in <module>
    mps_info.load_data(scratch + "/mps_info.bin")
RuntimeError: MPSInfo:load_data on '/central/scratchio/hczhai/hife/hfe2-def2-SVP-uks.6/runs/casci-22/node0/mps_info.bin' failed.
Traceback (most recent call last):
  File "/home/hczhai/program/anaconda3/envs/python3.7/bin/block2main", line 1379, in <module>
    mps_info.load_data(scratch + "/mps_info.bin")
RuntimeError: MPSInfo:load_data on '/central/scratchio/hczhai/hife/hfe2-def2-SVP-uks.6/runs/casci-22/node0/mps_info.bin' failed.
Traceback (most recent call last):
  File "/home/hczhai/program/anaconda3/envs/python3.7/bin/block2main", line 1379, in <module>
    mps_info.load_data(scratch + "/mps_info.bin")
RuntimeError: MPSInfo:load_data on '/central/scratchio/hczhai/hife/hfe2-def2-SVP-uks.6/runs/casci-22/node0/mps_info.bin' failed.
Traceback (most recent call last):
  File "/home/hczhai/program/anaconda3/envs/python3.7/bin/block2main", line 1379, in <module>
    mps_info.load_data(scratch + "/mps_info.bin")
RuntimeError: MPSInfo:load_data on '/central/scratchio/hczhai/hife/hfe2-def2-SVP-uks.6/runs/casci-22/node0/mps_info.bin' failed.
Traceback (most recent call last):
  File "/home/hczhai/program/anaconda3/envs/python3.7/bin/block2main", line 1379, in <module>
    mps_info.load_data(scratch + "/mps_info.bin")
RuntimeError: MPSInfo:load_data on '/central/scratchio/hczhai/hife/hfe2-def2-SVP-uks.6/runs/casci-22/node0/mps_info.bin' failed.
--------------------------------------------------------------------------
Primary job  terminated normally, but 1 process returned
a non-zero exit code. Per user-direction, the job has been aborted.
--------------------------------------------------------------------------
--------------------------------------------------------------------------
orterun detected that one or more processes exited with non-zero status, thus causing
the job to be terminated. The first process to do so was:

  Process name: [[40967,1],1]
  Exit code:    1
--------------------------------------------------------------------------
ERROR TERMINATION
